Workbook
Name Slicer_Sale_Category: #REF!
Name Slicer_Date: #REF!
Name Slicer_Car_Age: #REF!
Name Slicer_Sale_Month: #REF!

Sheet Sheet1
J3: SALES ANALYSIS REPORT

Sheet Sheet3
A3: Row Labels | B3: Sum of Sale Price | C3: Sum of Commission Earned | D3: Sum of profit | H3: Row Labels | I3: Sum of Sale Price | J3: Sum of profit
A4: David Lee | B4: 130390 | C4: 13238.55 | D4: 26078 | H4: Chevrolet | I4: 17374031 | J4: 3474806.2
A5: Elizabeth Brown | B5: 86875 | C5: 10290.77 | D5: 17375 | H5: Ford | I5: 19454032 | J5: 3890806.4
A6: James Gomez | B6: 89909 | C6: 7706.84 | D6: 17981.8 | H6: Honda | I6: 17969784 | J6: 3593956.8
A7: Kimberly Hall | B7: 94418 | C7: 11779.62 | D7: 18883.6 | H7: Nissan | I7: 17190395 | J7: 3438079
A8: Michael Parker | B8: 91038 | C8: 6153.83 | D8: 18207.6 | H8: Toyota | I8: 18324311 | J8: 3664862.2
A9: Michael Sullivan | B9: 86883 | C9: 8088.66 | D9: 17376.6 | H9: Grand Total | I9: 90312553 | J9: 18062511
A10: Sarah Johnson | B10: 94172 | C10: 11714.45 | D10: 18834.4
A11: Shawn James | B11: 90040 | C11: 11402.31 | D11: 18008
A12: Stephanie Jones | B12: 104428 | C12: 13771.91 | D12: 20885.6
A13: Stephanie Smith | B13: 146576 | C13: 15070.81 | D13: 29315.2
A14: Grand Total | B14: 1014729 | C14: 109217.75 | D14: 202945.8
G18: Row Labels | H18: Sum of Sale Price | I18: Sum of profit
G19: January | H19: 8603302 | I19: 1720660.4
G20: February | H20: 6247777 | I20: 1249555.4
G21: March | H21: 7232801 | I21: 1446560.2
G22: April | H22: 8001002 | I22: 1600200.4
G23: May | H23: 7861367 | I23: 1572273.4
G24: June | H24: 7192051 | I24: 1438410.2
G25: July | H25: 7235239 | I25: 1447047.8
G26: August | H26: 7972317 | I26: 1594463.4
G27: September | H27: 7545291 | I27: 1509058.2
G28: October | H28: 7472137 | I28: 1494427.4
G29: November | H29: 7057209 | I29: 1411441.8
G30: December | H30: 7892060 | I30: 1578412
G31: Grand Total | H31: 90312553 | I31: 18062511
A39: Row Labels | B39: Sum of profit | C39: Sum of Sale Price
A40: Budget | B40: 2202834.8 | C40: 11014174
A41: Mid Range | B41: 9133742 | C41: 45668710
A42: Premium | B42: 6725933.8 | C42: 33629669
A43: Grand Total | B43: 18062511 | C43: 90312553
A55: Sum of profit | B55: Column Labels
A56: Row Labels | B56: Ford | C56: Honda | D56: Toyota | E56: Grand Total
A57: 3 | B57: 304364.4 | C57: 347798.2 | D57: 271496 | E57: 923658.6
A58: 4 | B58: 312661.6 | C58: 349302.8 | D58: 261247.8 | E58: 923212.2
A59: 5 | B59: 313982 | C59: 298914.6 | D59: 297997.2 | E59: 910893.8
A60: 6 | B60: 287916.6 | C60: 229314 | D60: 341910.4 | E60: 859141
A61: 7 | B61: 339506.2 | C61: 236484.2 | D61: 332890.2 | E61: 908880.6
A62: 8 | B62: 343546.6 | C62: 279968 | D62: 256524.2 | E62: 880038.8
A63: 9 | B63: 256546 | C63: 408165.6 | D63: 252110.2 | E63: 916821.8
...

Sheet  car_sales_data 1
A1: Date | B1: Salesperson | C1: Customer Name | D1: Car Make | E1: Car Model | F1: Car Year | G1: Sale Price | H1: Commission Earned | I1: profit | J1: Sale Month | K1: Sale Category | L1: Car Age
A2: 44774 | B2: Monica Moore MD | C2: Mary Butler | D2: Nissan | E2: Altima | F2: 2018 | G2: 15983 | H2: 1126.73 | I2: =' car_sales_data 1'!$G2*0.2 -> 3196.6 | J2: =TEXT(' car_sales_data 1'!$A2,"mmmm") -> August | K2: =IF(' car_sales_data 1'!$G2>40000,"Premium", IF(' car_sales_data 1'!$G2>=20000,"Mid Range","Budget")) -> Budget | L2: =YEAR(TODAY())-' car_sales_data 1'!$F2 -> 7
A3: 45000 | B3: Roberto Rose | C3: Richard Pierce | D3: Nissan | E3: F-150 | F3: 2016 | G3: 38474 | H3: 5172.4 | I3: =' car_sales_data 1'!$G3*0.2 -> 7694.8 | J3: =TEXT(' car_sales_data 1'!$A3,"mmmm") -> March | K3: =IF(' car_sales_data 1'!$G3>40000,"Premium", IF(' car_sales_data 1'!$G3>=20000,"Mid Range","Budget")) -> Mid Range | L3: =YEAR(TODAY())-' car_sales_data 1'!$F3 -> 9
A4: 45045 | B4: Ashley Ramos | C4: Sandra Moore | D4: Ford | E4: Civic | F4: 2016 | G4: 33340 | H4: 3818.63 | I4: =' car_sales_data 1'!$G4*0.2 -> 6668 | J4: =TEXT(' car_sales_data 1'!$A4,"mmmm") -> April | K4: =IF(' car_sales_data 1'!$G4>40000,"Premium", IF(' car_sales_data 1'!$G4>=20000,"Mid Range","Budget")) -> Mid Range | L4: =YEAR(TODAY())-' car_sales_data 1'!$F4 -> 9
A5: 44808 | B5: Patrick Harris | C5: Johnny Scott | D5: Ford | E5: Altima | F5: 2013 | G5: 41937 | H5: 3866.2 | I5: =' car_sales_data 1'!$G5*0.2 -> 8387.4 | J5: =TEXT(' car_sales_data 1'!$A5,"mmmm") -> September | K5: =IF(' car_sales_data 1'!$G5>40000,"Premium", IF(' car_sales_data 1'!$G5>=20000,"Mid Range","Budget")) -> Premium | L5: =YEAR(TODAY())-' car_sales_data 1'!$F5 -> 12
A6: 44728 | B6: Eric Lopez | C6: Vanessa Jones | D6: Honda | E6: Silverado | F6: 2022 | G6: 20256 | H6: 2298.85 | I6: =' car_sales_data 1'!$G6*0.2 -> 4051.2 | J6: =TEXT(' car_sales_data 1'!$A6,"mmmm") -> June | K6: =IF(' car_sales_data 1'!$G6>40000,"Premium", IF(' car_sales_data 1'!$G6>=20000,"Mid Range","Budget")) -> Mid Range | L6: =YEAR(TODAY())-' car_sales_data 1'!$F6 -> 3
A7: 44913 | B7: Terry Perkins MD | C7: John Olsen | D7: Ford | E7: Altima | F7: 2015 | G7: 14769 | H7: 1140.86 | I7: =' car_sales_data 1'!$G7*0.2 -> 2953.8 | J7: =TEXT(' car_sales_data 1'!$A7,"mmmm") -> December | K7: =IF(' car_sales_data 1'!$G7>40000,"Premium", IF(' car_sales_data 1'!$G7>=20000,"Mid Range","Budget")) -> Budget | L7: =YEAR(TODAY())-' car_sales_data 1'!$F7 -> 10
A8: 44724 | B8: Ashley Brown | C8: Tyler Lawson | D8: Honda | E8: F-150 | F8: 2013 | G8: 41397 | H8: 5910.67 | I8: =' car_sales_data 1'!$G8*0.2 -> 8279.4 | J8: =TEXT(' car_sales_data 1'!$A8,"mmmm") -> June | K8: =IF(' car_sales_data 1'!$G8>40000,"Premium", IF(' car_sales_data 1'!$G8>=20000,"Mid Range","Budget")) -> Premium | L8: =YEAR(TODAY())-' car_sales_data 1'!$F8 -> 12
A9: 44732 | B9: Norma Watkins | C9: Michael Bond | D9: Ford | E9: Altima | F9: 2015 | G9: 46233 | H9: 3311.38 | I9: =' car_sales_data 1'!$G9*0.2 -> 9246.6 | J9: =TEXT(' car_sales_data 1'!$A9,"mmmm") -> June | K9: =IF(' car_sales_data 1'!$G9>40000,"Premium", IF(' car_sales_data 1'!$G9>=20000,"Mid Range","Budget")) -> Premium | L9: =YEAR(TODAY())-' car_sales_data 1'!$F9 -> 10
A10: 44806 | B10: Scott Parker | C10: Stephanie Smith | D10: Ford | E10: Corolla | F10: 2021 | G10: 27337 | H10: 2720.13 | I10: =' car_sales_data 1'!$G10*0.2 -> 5467.4 | J10: =TEXT(' car_sales_data 1'!$A10,"mmmm") -> September | K10: =IF(' car_sales_data 1'!$G10>40000,"Premium", IF(' car_sales_data 1'!$G10>=20000,"Mid Range","Budget")) -> Mid Range | L10: =YEAR(TODAY())-' car_sales_data 1'!$F10 -> 4
A11: 45022 | B11: Andrew Smith | C11: Ashley Moreno DDS | D11: Ford | E11: Civic | F11: 2018 | G11: 16309 | H11: 2445.14 | I11: =' car_sales_data 1'!$G11*0.2 -> 3261.8 | J11: =TEXT(' car_sales_data 1'!$A11,"mmmm") -> April | K11: =IF(' car_sales_data 1'!$G11>40000,"Premium", IF(' car_sales_data 1'!$G11>=20000,"Mid Range","Budget")) -> Budget | L11: =YEAR(TODAY())-' car_sales_data 1'!$F11 -> 7
A12: 44997 | B12: Harold Nelson | C12: Isaac Patton | D12: Honda | E12: Silverado | F12: 2021 | G12: 41259 | H12: 3818.16 | I12: =' car_sales_data 1'!$G12*0.2 -> 8251.8 | J12: =TEXT(' car_sales_data 1'!$A12,"mmmm") -> March | K12: =IF(' car_sales_data 1'!$G12>40000,"Premium", IF(' car_sales_data 1'!$G12>=20000,"Mid Range","Budget")) -> Premium | L12: =YEAR(TODAY())-' car_sales_data 1'!$F12 -> 4
A13: 44955 | B13: Richard Richardson | C13: Justin Gray | D13: Toyota | E13: Silverado | F13: 2022 | G13: 48224 | H13: 4368.72 | I13: =' car_sales_data 1'!$G13*0.2 -> 9644.8 | J13: =TEXT(' car_sales_data 1'!$A13,"mmmm") -> January | K13: =IF(' car_sales_data 1'!$G13>40000,"Premium", IF(' car_sales_data 1'!$G13>=20000,"Mid Range","Budget")) -> Premium | L13: =YEAR(TODAY())-' car_sales_data 1'!$F13 -> 3
... A3000: 44731 | B3000: Alexandra Hudson | C3000: Brian Fuller | D3000: Chevrolet | E3000: F-150 | F3000: 2016 | G3000: 10299 | H3000: 1430.27 | I3000: =' car_sales_data 1'!$G3000*0.2 -> 2059.8 | J3000: =TEXT(' car_sales_data 1'!$A3000,"mmmm") -> June | K3000: =IF(' car_sales_data 1'!$G3000>40000,"Premium", IF(' car_sales_data 1'!$G3000>=20000,"Mid Range","Budget")) -> Budget | L3000: =YEAR(TODAY())-' car_sales_data 1'!$F3000 -> 9
